<?xml version="1.0"?>

<!-- 
This is the xacro description of a Pioneer 3DX, to be used in rviz and gazebo.
Copyright (C) 2013 Rafael Berkvens rafael.berkvens@uantwerpen.be

This program is free software: you can redistribute it and/or modify
it under the terms of the GNU General Public License as published by
the Free Software Foundation, either version 3 of the License, or
(at your option) any later version.

This program is distributed in the hope that it will be useful,
but WITHOUT ANY WARRANTY; without even the implied warranty of
MERCHANTABILITY or FITNESS FOR A PARTICULAR PURPOSE.  See the
GNU General Public License for more details.

You should have received a copy of the GNU General Public License
along with this program.  If not, see <http://www.gnu.org/licenses/>.

This project is based on work by Tracy Davies, where it was in turn based on
work original in ucs-ros-pkg.
 -->

<robot name="pioneer3dx" xmlns:xacro="http://ros.org/wiki/xacro">

  <!-- import all gazebo-customization elements, including gazebo colors -->
  <xacro:include filename="$(find p3dx_description)/urdf/pioneer3dx.gazebo" />
  <!-- import the pioneer 3dx's wheels -->
  <xacro:include filename="$(find p3dx_description)/urdf/pioneer3dx_wheel.xacro" />

  <!-- chassis -->
	<link name="base_link">
		<inertial>
			<mass value="3.5" />
			<!--<origin xyz="-0.025 0 -0.223"/> -->
			<origin xyz="-0.05 0 0" />
			<inertia ixx="1" ixy="0" ixz="0" iyy="1" iyz="0" izz="1" />
		</inertial>

		<visual name="base_visual">
			<origin xyz="-0.045 0 0.148" rpy="0 0 0" />
			<geometry name="pioneer_geom">
				<mesh filename="package://p3dx_description/meshes/chassis.stl" />
			</geometry>
			<material name="ChassisRed">
				<color rgba="0.851 0.0 0.0 1.0" />
			</material>
		</visual>

		<collision>
			<origin xyz="-0.045 0 0.145" rpy="0 0 0" />
			<geometry>
				<box size="0.35 0.25 0.14" />
			</geometry>
		</collision>
	</link>


	<!-- my code starts-->
<!--
	<link name="camera">
    <collision>
      <origin xyz="0 5 0" rpy="0 0 0"/>
      <geometry>
        <box size="0.05 0.05 0.05"/>
      </geometry>
    </collision>

    <visual>
      <origin xyz="0 0 0" rpy="0 0 0"/>
      <geometry>
        <box size="0.05 0.05 0.05"/>
      </geometry>
      <material name="green"/>
    </visual>

    <inertial>
      <mass value="0.1" />
      <origin xyz="0 0 0" rpy="0 0 0"/>
      <box_inertia m="0.1" x="0.05" y="0.05" z="0.05" />
      <inertia ixx="1e-6" ixy="0" ixz="0" iyy="1e-6" iyz="0" izz="1e-6" />
    </inertial>
  </link>

  <joint name="camera_joint" type="fixed">
    <axis xyz="0 1 0" />
    <origin xyz=".2 0 0" rpy="0 0 0"/>
    <parent link="top_plate"/>
    <child link="camera"/>
  </joint>
-->
<!-- my code ends -->






  <!-- top_plate -->
	<link name="top_plate">
		<inertial>
			<mass value="0.01" />
			<origin xyz="0 0 0" />
			<inertia ixx="1" ixy="0" ixz="0" iyy="1" iyz="0" izz="1" />
		</inertial>

		<visual name="base_visual">
			<origin xyz="0 0 0" rpy="0 0 0" />
			<geometry name="top_geom">
				<mesh filename="package://p3dx_description/meshes/top.stl" />
			</geometry>

			<material name="TopBlack">
				<color rgba="0.038 0.038 0.038 1.0" />
			</material>
		</visual>

		<collision>
			<origin xyz="0.0 0 0" rpy="0 0 0" />
			<geometry name="pioneer_geom">
				<box size="0.45 0.38 0.01" />
			</geometry>
		</collision>
	</link>

	<joint name="base_top_joint" type="fixed">
		<origin xyz="-0.045 0 0.234" rpy="0 0 0" />
		<parent link="base_link" />
		<child link="top_plate" />
	</joint>

  <!-- swivel -->
	<link name="swivel">
		<inertial>
			<mass value="0.1" />
			<origin xyz="0 0 0" />
			<inertia ixx="0.01" ixy="0" ixz="0" iyy="0.01" iyz="0" izz="0.01" />
		</inertial>

		<visual name="base_visual">
			<origin xyz="0 0 0" rpy="0 0 0" />
			<geometry name="pioneer_geom">
				<mesh filename="package://p3dx_description/meshes/swivel.stl" />
			</geometry>
			<material name="swivel">
				<color rgba="0.5 0.5 0.5 1" />
			</material>
		</visual>

		<collision>
			<origin xyz="0 0 0" rpy="0 0 0" />
			<geometry>
				<box size="0 0 0" />
			</geometry>
		</collision>
	</link>

	<joint name="base_swivel_joint" type="continuous">
		<origin xyz="-0.185 0 0.055" rpy="0 0 0" />
		<axis xyz="0 0 1" />
		<anchor xyz="0 0 0" />
		<limit effort="100" velocity="100" k_velocity="0" />
		<joint_properties damping="0.0" friction="0.0" />
		<parent link="base_link" />
		<child link="swivel" />
	</joint>

  <!-- center_hubcap -->
	<link name="center_hubcap">
		<inertial>
			<mass value="0.01" />
			<origin xyz="0 0 0" />
			<inertia ixx="0.012411765597" ixy="-0.000711733678" ixz="0.00050272983"
				iyy="0.015218160428" iyz="-0.000004273467" izz="0.011763977943" />
		</inertial>

		<visual name="base_visual">
			<origin xyz="0 0 0" rpy="0 0 0" />
			<geometry name="pioneer_geom">
				<mesh filename="package://p3dx_description/meshes/center_hubcap.stl" />
			</geometry>
			<material name="swivel">
				<color rgba="0.5 0.5 0.5 1" />
			</material>
		</visual>

		<collision>
			<origin xyz="0 0 0" rpy="0 0 0" />
			<geometry>
				<box size="0 0 0" />
			</geometry>
		</collision>
	</link>

	<joint name="swivel_hubcap_joint" type="continuous">
		<origin xyz="-0.026 0 -0.016" rpy="0 0 0" />
		<axis xyz="0 1 0" />
		<anchor xyz="0 0 0" />
		<limit effort="100" velocity="100" k_velocity="0" />
		<joint_properties damping="0.0" friction="0.0" />
		<parent link="swivel" />
		<child link="center_wheel" />
	</joint>

  <!-- center_wheel -->
	<link name="center_wheel">
		<inertial>
			<mass value="0.1" />
			<origin xyz="0 0 0" />
			<inertia ixx="0.012411765597" ixy="-0.000711733678" ixz="0.00050272983"
				iyy="0.015218160428" iyz="-0.000004273467" izz="0.011763977943" />
		</inertial>

		<visual name="base_visual">
			<origin xyz="0 0 0" rpy="0 0 0" />
			<geometry name="pioneer_geom">
				<mesh filename="package://p3dx_description/meshes/center_wheel.stl" />
			</geometry>
			<material name="WheelBlack">
				<color rgba="0.117 0.117 0.117 1" />
			</material>
		</visual>

		<collision>
			<origin xyz="0 0 0" rpy="${-3.1415927/2.0} 0 0" />
			<geometry>
				<cylinder radius="0.0375" length="0.01" />
			</geometry>
		</collision>
	</link>

	<joint name="center_wheel_joint" type="fixed">
		<origin xyz="-0.0035 0 -0.001" rpy="0 0 0"/>
		<parent link="center_wheel"/>
		<child link="center_hubcap"/>
	</joint>

	<xacro:p3dx_wheel suffix="left" parent="base_link" reflect="1"/>
	<xacro:p3dx_wheel suffix="right" parent="base_link" reflect="-1"/>

  <!-- front_sonar -->
	<link name="front_sonar">
		<inertial>
			<mass value="0.0001" />
			<origin xyz="0 0 0" />
			<inertia ixx="1" ixy="0" ixz="0" iyy="1" iyz="0" izz="1" />
		</inertial>
		
		<visual name="front_sonar_vis">
			<origin rpy="0 0 0" xyz="0 0 0" />
			<geometry name="pioneer_geom">
				<mesh filename="package://p3dx_description/meshes/front_sonar.stl" />
			</geometry>
			<material name="SonarYellow">
				<color rgba="0.715 0.583 0.210 1.0" />
			</material>
		</visual>
		
		<collision>
			<origin rpy="0 0 0" xyz="0 0 0" />
			<geometry>
				<box size="0 0 0" />
			</geometry>
		</collision>
	</link>
	
	<joint name="base_front_joint" type="fixed">
		<origin rpy="0 0 0" xyz="0.109 0 0.209" />
		<parent link="base_link" />
		<child link="front_sonar" />
	</joint>




<!--<link name="lms100">
		<inertial>
			<mass value="1e-5" />
			<origin xyz="0 0 0" rpy="0 0 0" />
			<inertia ixx="1e-6" ixy="0" ixz="0" iyy="1e-6" iyz="0" izz="1e-6" />
		</inertial>

		<visual>
			<origin xyz="0 0 0" rpy="0 0 0" />
			<geometry>
				<mesh filename="package://p3dx_description/meshes/lms100.dae" />     
			</geometry>
		</visual>

		<collision>
			<origin xyz="0 0 0" rpy="0 0 0" />
			<geometry>
				<box size="0.1 0.1 0.1" />
			</geometry>
		</collision>
	</link>-->

<!--<link name="lidar_base">
		<inertial>
			<mass value="1e-5" />
			<origin xyz="0 0 0" rpy="0 0 0" />
			<inertia ixx="1e-6" ixy="0" ixz="0" iyy="1e-6" iyz="0" izz="1e-6" />
		</inertial>

		<visual>
			<origin xyz="0 0 0" rpy="0 0 0" />
			<geometry>
				<mesh filename="package://p3dx_description/meshes/velodyne_top.dae" />     
			</geometry>
		</visual>

		<collision>
			<origin xyz="0 0 0" rpy="0 0 0" />
			<geometry>
				<box size="0.1 0.1 0.1" />
			</geometry>
		</collision>
	</link>-->

	<!--<joint name="lidar_joint1" type="fixed">
		<axis xyz="0 1 0" />
		<origin xyz="0.16 0 0.15" rpy="0 0 0" />
		<parent link="base_link" />
		<child link="lms100" />
	</joint>-->
	<!--<joint name="lidar_joint2" type="fixed">
		<axis xyz="0 1 0" />
		<origin xyz="0.16 0 0.15" rpy="0 0 0" />
		<parent link="base_link" />
		<child link="lms100" />
	</joint>-->








	
	<!-- lms100 laser -->
	<link name="lidarbase">
		<inertial>
			<mass value="1.2" />
			<origin xyz="0 0 0" rpy="0 0 0" />
			<inertia ixx="0.001087473" ixy="0" ixz="0" iyy="0.001087473" iyz="0" izz="0.001092437" />
		</inertial>

		<visual>
			<origin xyz="0 0 0" rpy="0 0 0" />
			<geometry>
				<mesh filename="package://p3dx_description/meshes/velodyne_base.dae" />     
			</geometry>
		</visual>

		<collision>
			<origin xyz="0 0 0" rpy="0 0 0" />
			<geometry>
				<box size="0.1 0.1 0.1" />
			</geometry>
		</collision>
	</link>

	<link name="lidartop">
		<inertial>
			<mass value="1.2" />
			<origin xyz="0 0 0" rpy="0 0 0" />
			<inertia ixx="0.001087473" ixy="0" ixz="0" iyy="0.001087473" iyz="0" izz="0.001092437" />
		</inertial>

		<visual>
			<origin xyz="0 0 0" rpy="0 0 0" />
			<geometry>
				<mesh filename="package://p3dx_description/meshes/velodyne_top.dae" />     
			</geometry>
		</visual>

		<collision>
			<origin xyz="0 0 0" rpy="0 0 0" />
			<geometry>
				<box size="0.1 0.1 0.1" />
			</geometry>
		</collision>

	<sensor type="ray" name="sensor">
        <pose>0 0 -0.004645 1.5707 0 0</pose>
        <visualize>true</visualize>
        <update_rate>30</update_rate>
        <ray>
          <noise>
            <type>gaussian</type>
            <mean>0.0</mean>
            <stddev>0.1</stddev>
          </noise>

          <scan>
            <horizontal>
              <samples>32</samples>
              <resolution>1</resolution>
              <min_angle>-0.53529248</min_angle>
              <max_angle>0.18622663</max_angle>
            </horizontal>
          </scan>

          <range>
            <min>0.1</min>
            <max>70</max>
            <resolution>0.02</resolution>
          </range>
        </ray>
      </sensor>


	</link>

	<joint name="lidar_joint" type="fixed">
		<axis xyz="0 1 0" />
		<origin xyz="0 0 0" rpy="0 0 0" />
		<parent link="top_plate" />
		<child link="lidarbase" />
	</joint>

	<joint name="lidar_joint1" type="fixed">
		<axis xyz="0 1 0" />
		<origin xyz="0 0 0.05" rpy="0 0 0" />
		<parent link="top_plate" />
		<child link="lidartop" />
	</joint>


<!-- lidar connection-->

<!--
    <link name="base">
      <pose>0 0 0.029335 0 0 0</pose>
      <inertial>
        <mass>1.2</mass>
        <inertia>
          <ixx>0.001087473</ixx>
          <iyy>0.001087473</iyy>
          <izz>0.001092437</izz>
          <ixy>0</ixy>
          <ixz>0</ixz>
          <iyz>0</iyz>
        </inertia>
      </inertial>
      <collision name="base_collision">
        <geometry>
          <cylinder>
            <radius>.04267</radius>
            <length>.05867</length>
          </cylinder>
        </geometry>
      </collision>
      <visual name="base_visual">
        <pose>0 0 -0.029335 0 0 0</pose>
        <geometry>
          <mesh>
            <uri>model://velodyne_hdl32/meshes/velodyne_base.dae</uri>
          </mesh>
        </geometry>
      </visual>
    </link>
    
    <link name="top">
      <pose>0 0 0.095455 0 0 0</pose>
      <inertial>
        <mass>0.1</mass>
        <inertia>
          <ixx>0.000090623</ixx>
          <iyy>0.000090623</iyy>
          <izz>0.000091036</izz>
          <ixy>0</ixy>
          <ixz>0</ixz>
          <iyz>0</iyz>
        </inertia>
      </inertial>
      <collision name="top_collision">
        <geometry>
          <cylinder>
            <radius>0.04267</radius>
            <length>0.07357</length>
          </cylinder>
        </geometry>
      </collision>
      <visual name="top_visual">
        <pose>0 0 -0.0376785 0 0 1.5707</pose>
        <geometry>
          <mesh>
            <uri>model://velodyne_hdl32/meshes/velodyne_top.dae</uri>
          </mesh>
        </geometry>
      </visual>

      <sensor type="ray" name="sensor">
        <pose>0 0 -0.004645 1.5707 0 0</pose>
        <visualize>true</visualize>
        <update_rate>30</update_rate>
        <ray>
          <noise>
            <type>gaussian</type>
            <mean>0.0</mean>
            <stddev>0.1</stddev>
          </noise>

          <scan>
            <horizontal>
              <samples>32</samples>
              <resolution>1</resolution>
              <min_angle>-0.53529248</min_angle>
              <max_angle>0.18622663</max_angle>
            </horizontal>
          </scan>

          <range>
            <min>0.1</min>
            <max>70</max>
            <resolution>0.02</resolution>
          </range>
        </ray>
      </sensor>
    </link>

    <joint type="revolute" name="joint">
      <pose>0 0 -0.036785 0 0 0</pose>
      <parent link="top_plate"/>
      <child>top</child>
      <axis>
        <xyz>0 0 1</xyz>
        <limit>
          <lower>-10000000000000000</lower>
          <upper>10000000000000000</upper>
        </limit>
      </axis>
    </joint>
-->


<!-- lidar connection-->

<!--my code


      <link name='base'>
        <pose frame=''>0 0 0.029335 0 -0 0</pose>
        <inertial>
          <mass>1.2</mass>
          <inertia>
            <ixx>0.00108747</ixx>
            <iyy>0.00108747</iyy>
            <izz>0.00109244</izz>
            <ixy>0</ixy>
            <ixz>0</ixz>
            <iyz>0</iyz>
          </inertia>
        </inertial>
        <collision name='base_collision'>
          <geometry>
            <cylinder>
              <radius>0.04267</radius>
              <length>0.05867</length>
            </cylinder>
          </geometry>
        </collision>
        <visual name='base_visual'>
          <pose frame=''>0 0 -0.029335 0 -0 0</pose>
          <geometry>
            <mesh>
              <uri>model://velodyne_hdl32/meshes/velodyne_base.dae</uri>
            </mesh>
          </geometry>
        </visual>
      </link>
      <link name='top'>
        <pose frame=''>0 0 0.095455 0 -0 0</pose>
        <inertial>
          <mass>0.1</mass>
          <inertia>
            <ixx>9.0623e-05</ixx>
            <iyy>9.0623e-05</iyy>
            <izz>9.1036e-05</izz>
            <ixy>0</ixy>
            <ixz>0</ixz>
            <iyz>0</iyz>
          </inertia>
        </inertial>
        <collision name='top_collision'>
          <geometry>
            <cylinder>
              <radius>0.04267</radius>
              <length>0.07357</length>
            </cylinder>
          </geometry>
        </collision>
        <visual name='top_visual'>
          <pose frame=''>0 0 -0.037679 0 -0 1.5707</pose>
          <geometry>
            <mesh>
              <uri>model://velodyne_hdl32/meshes/velodyne_top.dae</uri>
            </mesh>
          </geometry>
        </visual>
        <sensor name='sensor' type='ray'>
          <pose frame=''>0 0 -0.004645 1.5707 -0 0</pose>
          <visualize>1</visualize>
          <update_rate>30</update_rate>
          <ray>
            <noise>
              <type>gaussian</type>
              <mean>0</mean>
              <stddev>0.1</stddev>
            </noise>
            <scan>
              <horizontal>
                <samples>32</samples>
                <resolution>1</resolution>
                <min_angle>-0.535292</min_angle>
                <max_angle>0.186227</max_angle>
              </horizontal>
            </scan>
            <range>
              <min>0.1</min>
              <max>70</max>
              <resolution>0.02</resolution>
            </range>
          </ray>
        </sensor>
      </link>
      <joint name='joint' type='revolute'>
        <pose frame=''>0 0 -0.036785 0 -0 0</pose>
        <parent>base</parent>
        <child>top</child>
        <axis>
          <xyz>0 0 1</xyz>
          <limit>
            <lower>-1e+16</lower>
            <upper>1e+16</upper>
          </limit>
          <use_parent_model_frame>0</use_parent_model_frame>
        </axis>
      </joint>
      <pose frame=''>-0.701772 0.531559 0.001683 0 -0 0</pose>



my code-->


</robot>
